<sdf version='1.6'>
    <model name='ActiveSensor' canonical_link='body'>

        <link name='body'>
            <pose>0 0 0 0 0 0</pose>

            <inertial> <!--inertial properties of the link mass, inertia matix-->
                <mass>5</mass>
                <inertia>
                    <ixx>0.095329</ixx>
                    <ixy>0</ixy>
                    <ixz>0</ixz>
                    <iyy>0.381317</iyy>
                    <iyz>0</iyz>
                    <izz>0.476646</izz>
                </inertia>
            </inertial>

            <collision name='collision_base'>
                <pose>0 0 0.0175015175 0 0 0</pose>
                <geometry>
                    <box>
                        <size>0.05001062 0.05001062 0.035003035</size>
                    </box>
                </geometry>
            </collision>

            <collision name='collision_top'>
                <pose>0 0 0.0525045525 0 0 0</pose>
                <geometry>
                    <cylinder>
                        <radius>0.02</radius>
                        <length>0.035003035</length>
                    </cylinder>
                </geometry>
            </collision>

            <visual name='visual'>
                <pose>0 0 0 0 0 1.5707</pose>
                <geometry>
                    <mesh>
                        <uri>file://resources/active_sensor/meshes/hokuyo_urg04lx.dae</uri>
                        <scale>10 10 10</scale>
                    </mesh>
                </geometry>   
            </visual>
        </link>
        
        <link name='sensor'>
            <pose>0.3 0 0.5 0 1.5707 0</pose>
            <inertial>
                <mass>0.1</mass>
                <inertia>
                    <ixx>0.000166667</ixx>
                    <iyy>0.000166667</iyy>
                    <izz>0.000166667</izz>
                </inertia>
            </inertial>

            <collision name="collision">
                <geometry>
                    <cylinder>
                        <radius>0.05</radius>
                        <length>0.2</length>
                    </cylinder>
                </geometry>
            </collision>

            <visual name="visual">
                <geometry>
                    <cylinder>
                        <radius>0.05</radius>
                        <length>0.2</length>
                    </cylinder>
                </geometry>
            </visual>

            <sensor name='gpu_lidar' type='gpu_lidar'>"
                <pose>0 0 0 0 -1.5707 0</pose>
                <topic>ActiveSensor/lidar</topic>
                <update_rate>5</update_rate>

                <ray>
                    <scan>
                        <horizontal>
                            <samples>121</samples>
                            <resolution>1</resolution>
                            <min_angle>-1.047</min_angle>
                            <max_angle>1.047</max_angle>
                        </horizontal>
                        <vertical>
                            <samples>1</samples>
                            <resolution>0.01</resolution>
                            <min_angle>0</min_angle>
                            <max_angle>0</max_angle>
                        </vertical>
                    </scan>
                    <range>
                        <min>0.08</min>
                        <max>10.0</max>
                        <resolution>1</resolution>
                    </range>
                </ray>
                <always_on>1</always_on>
                <visualize>false</visualize>
            </sensor>
        </link>       

        <link name='left_wheel'>
            <pose relative_to="body">-0.3 0.3 0.15 -1.5707 0 0</pose>

            <inertial>
                <mass>1</mass>
                <inertia>
                    <ixx>0.013333</ixx>
                    <ixy>0</ixy>
                    <ixz>0</ixz>
                    <iyy>0.013333</iyy>
                    <iyz>0</iyz>
                    <izz>0.02</izz>
                </inertia>
            </inertial>

            <visual name='visual'>
                <geometry>
                    <cylinder>
                        <radius>0.2</radius>
                        <length>0.1</length>
                    </cylinder>
                </geometry>
                <material>
                    <ambient>0.0 0.0 0.0 1</ambient>
                    <diffuse>0.0 0.0 0.0 1</diffuse>
                    <specular>0.0 0.0 0.0 1</specular>
                </material>
            </visual>

            <collision name='collision'>
                <geometry>
                    <cylinder>
                        <radius>0.2</radius>
                        <length>0.1</length>
                    </cylinder>
                </geometry>
            </collision>
        </link>

        <link name='right_wheel'>
            <pose relative_to="body">-0.3 -0.3 0.15 -1.5707 0 0</pose> <!--angles are in radian-->

            <inertial>
                <mass>1</mass>
                <inertia>
                    <ixx>0.013333</ixx>
                    <ixy>0</ixy>
                    <ixz>0</ixz>
                    <iyy>0.013333</iyy>
                    <iyz>0</iyz>
                    <izz>0.02</izz>
                </inertia>
            </inertial>

            <visual name='visual'>
                <geometry>
                    <cylinder>
                        <radius>0.2</radius>
                        <length>0.1</length>
                    </cylinder>
                </geometry>
                <material>
                    <ambient>0.0 0.0 0.0 1</ambient>
                    <diffuse>0.0 0.0 0.0 1</diffuse>
                    <specular>0.0 0.0 0.0 1</specular>
                </material>
            </visual>

            <collision name='collision'>
                <geometry>
                    <cylinder>
                        <radius>0.2</radius>
                        <length>0.1</length>
                    </cylinder>
                </geometry>
            </collision>
        </link>

        <frame name="caster_frame" attached_to='body'>
            <pose>0.15 0 0.0 0 0 0</pose>
        </frame>

        <link name='caster'>
            <pose relative_to='caster_frame'/>

            <inertial>
                <mass>3</mass>
                <inertia>
                    <ixx>0.016</ixx>
                    <ixy>0</ixy>
                    <ixz>0</ixz>
                    <iyy>0.016</iyy>
                    <iyz>0</iyz>
                    <izz>0.016</izz>
                </inertia>
            </inertial>

            <visual name='visual'>
                <geometry>
                    <sphere>
                        <radius>0.08</radius>
                    </sphere>
                </geometry>
                <material>
                    <ambient>0.0 0.0 0.0 1</ambient>
                    <diffuse>0.0 0.0 0.0 1</diffuse>
                    <specular>0.0 0.0 0.0 1</specular>
                </material>
            </visual>

            <collision name='collision'>
                <geometry>
                    <sphere>
                        <radius>0.08</radius>
                    </sphere>
                </geometry>
            </collision>
        </link>

        <joint name='left_wheel_joint' type='revolute'>
            <pose relative_to='left_wheel'/>   
            <parent>body</parent>
            <child>left_wheel</child>
            <axis>
                <xyz expressed_in='__model__'>0 1 0</xyz> <!--can be defined as any frame or even arbitrary frames-->
                <limit>
                    <lower>-1.79769e+308</lower>    <!--negative infinity-->
                    <upper>1.79769e+308</upper>     <!--positive infinity-->
                </limit>
            </axis>
        </joint>
        
        <joint name="lidar_joint" type="fixed">
            <parent>body</parent>
            <child>sensor</child>
            <pose>0 0 0.15 0 0 0</pose>
        </joint>      

        <joint name='right_wheel_joint' type='revolute'>
            <pose relative_to='right_wheel'/>
            <parent>body</parent>
            <child>right_wheel</child>
            <axis>
                <xyz expressed_in='__model__'>0 1 0</xyz>
                <limit>
                    <lower>-1.79769e+308</lower>    <!--negative infinity-->
                    <upper>1.79769e+308</upper>     <!--positive infinity-->
                </limit>
            </axis>
        </joint>

        <joint name='caster_wheel' type='ball'>
            <parent>body</parent>
            <child>caster</child>
        </joint>
        
        <plugin filename="libignition-gazebo-diff-drive-system.so" name="ignition::gazebo::systems::DiffDrive">
            <left_joint>left_wheel_joint</left_joint>
            <right_joint>right_wheel_joint</right_joint>
            <wheel_separation>2</wheel_separation>
            <wheel_radius>0.1</wheel_radius>
            <topic>ActiveSensor/cmd_vel</topic>
        </plugin>
        
        <plugin name='ignition::gazebo::systems::OdometryPublisher' filename='ignition-gazebo-odometry-publisher-system'>
            <odom_topic>/ActiveSensor/odometry</odom_topic>
            <dimensions>3</dimensions>
        </plugin>
    </model>
</sdf>
